<mujoco>
  <option timestep="0.002"/>
  <compiler angle="degree" coordinate="local"/>
  
  <visual>
    <global  offwidth="160" offheight="90"/>
    <map znear="0.001" zfar="10.0"/>
    <rgba haze=".3 .3 .3 1"/>
    <!-- <scale> -->
      <!-- <global>0.1</global> Scale up small objects visually -->
    <!-- </scale> -->
  </visual>

  <asset>
    <texture builtin="gradient" height="100" rgb1="1 1 1" rgb2="0 0 0" type="skybox" width="100"/>
    <texture builtin="flat" height="1278" mark="cross" markrgb="1 1 1" name="texgeom" random="0.01" rgb1="0.8 0.6 0.4" rgb2="0.8 0.6 0.4" type="cube" width="127"/>
    <texture builtin="checker" height="100" name="texplane" rgb1="0 0 0" rgb2="0.8 0.8 0.8" type="2d" width="100"/>
    <material name="MatPlane" reflectance="0.5" shininess="1" specular="1" texrepeat="6.1 6.1" texture="texplane"/>
    <material name="geom" texture="texgeom" texuniform="true"/>

    <hfield name="HMap" file="hmap.png" size="0.5 0.5 0.03 0.02"/>
    <!-- <mesh name="tiles" file="mesh/tiles.obj" refquat="1 -1 0 0"/> -->
    <mesh file="assets/hexapod_body.stl" scale = "0.001 0.001 0.001"/>
    <mesh file="assets/leg hip.stl" scale = "0.001 0.001 0.001"/>
    <mesh file="assets/leg_top.stl" scale = "0.001 0.001 0.001"/>
    <mesh file="assets/leg_middle.stl" scale = "0.001 0.001 0.001"/>
    <mesh file="assets/foot_tip_no_foot.stl" scale = "0.001 0.001 0.001"/>
  </asset>

  <!-- Model Classes -->
  <default>
    <default class="body">
      <geom  type="box" condim="1" density="500"/>
      <joint type="hinge" damping="300" armature=".01" limited="true"/>
      <default class="yaw">
        <joint axis="0 0 1" range="-90 90"/>
        <position ctrlrange="-1.5708 1.5708"/>
        <!-- <geom fromto="0 0 0 0.1 0 0" size="0.01"/> -->
      </default>
      <default class="pitch">
        <joint axis="0 1 0" range="-60 60"/>
        <position ctrlrange="-1.0472 1.0472"/>
        <!-- <geom fromto="0 0 0 0.1 0 0" size="0.01"/> -->
      </default>
      <default class="knee">
          <joint axis="0 1 0" range="-90 120"/>
          <position ctrlrange="-1.5708 2.0944"/>
          <!-- <geom fromto="0 0 0 0.1 0 0" size="0.01"/> -->
        </default>
    </default>
    <!-- <position ctrllimited="true" kp="100000"/> -->
    <position ctrllimited="true" kp="100"/>
    
  </default>

  <!-- Model Layout -->`
  <worldbody>
    <light diffuse="0.5 0.5 0.5" pos="0 0 3" dir="0 0 -1"/>
    <!-- Floor -->
    <geom conaffinity="1" condim="3" material="MatPlane" name="floor" pos="0 0 0" rgba="0.8 0.9 0.8 1" size="2 2 2" type="plane"/>
    <geom conaffinity="1" condim="3" material="MatPlane" name="tiles" pos="0.8 0 0.001" rgba="0.8 0.9 0.8 1" type="hfield" hfield="HMap"/>
    <geom name="cube1" pos="2 2 0.03" size="0.1 0.1 0.1" type="box"/>
    <geom name="cube2" pos="2 -2 0.03" size="0.1 0.1 0.1" type="box"/>

    <!-- Stairs -->
    <geom pos="0 0.4 0" size="0.4 0.05 0.01" type="box"/>
    <geom pos="0 0.5 0" size="0.4 0.05 0.03" type="box"/>
    <geom pos="0 0.6 0" size="0.4 0.05 0.05" type="box"/>
    <geom pos="0 0.7 0" size="0.4 0.05 0.07" type="box"/>
    <geom pos="0 0.9 0" size="0.4 0.2 0.07" type="box"/>

    <!-- <geom pos="0 -7 -0.9" type="mesh" mesh="tiles"/> -->
    <body name="test_cube_10cm" pos ="0 0 0.3">
      <joint type="free" limited="false"/>    
      <geom type="box" size="0.05 0.05 0.05" density="1000"/>
    </body>


    <body name="torso" childclass="body" pos="-0.5 0 0.3" euler="0 0 0">
      <!-- Body -->
      <joint type="free" limited="false" damping="0"/>    
      <!-- <geom type="cylinder" size="0.07 0.015" rgba="0.9 0.9 0.5 1"/> -->
      <!-- <geom type="mesh" mesh="hexapod_body" mass="2.0" euler="90 0 0" pos = "-0.1 0.2 0"/> -->
      <geom type="mesh" mesh="hexapod_body" density="10000" />

      <geom type="mesh" mesh="leg hip" density="1000" pos="0.109 0.064 0" euler="0 0 30"/>
      <geom type="mesh" mesh="leg hip" density="1000" pos="0 0.126 0" euler="0 0 90"/>
      <geom type="mesh" mesh="leg hip" density="1000" pos="-0.109 0.064 0" euler="0 0 150"/>
      <geom type="mesh" mesh="leg hip" density="1000" pos="-0.109 -0.064 0" euler="0 0 210"/>
      <geom type="mesh" mesh="leg hip" density="1000" pos="0 -0.126 0" euler="0 0 270"/>
      <geom type="mesh" mesh="leg hip" density="1000" pos="0.109 -0.064 0" euler="0 0 330"/>

      <!-- Camera -->
      <body name="camera" pos="0.05 0 0.4">
        <camera name="cam" mode="fixed" fovy="60"/>
      </body>

      <!-- Front Left Leg -->
      <body pos="0.1087 0.06277 0" euler="0 0 30" childclass="yaw" name="front_left_leg">
        <joint name="front_left_yaw"/>
        <geom type="mesh" mesh="leg_top" density="1000"/>
        <body pos="0.0527 0 0.005" childclass="pitch">
          <joint name="front_left_pitch"/>
            <geom type="mesh" mesh="leg_middle" density="1000" pos="0.012 0 0.019"/>
          <body pos="0.1015 0 0.002" childclass="knee">
            <joint name="front_left_knee"/>
            <geom type="mesh" mesh="foot_tip_no_foot" density="1000" friction="2.0 0.1 0.1"/>
          </body>
        </body>
      </body>

      <!-- Front Right Leg -->
      <body pos="0.1087 -0.06277 0" euler="0 0 -30" childclass="yaw" name="front_right_leg">
        <joint name="front_right_yaw"/>
        <geom type="mesh" mesh="leg_top" density="1000"/>
        <body pos="0.0527 0 0.005" childclass="pitch">
          <joint name="front_right_pitch"/>
            <geom type="mesh" mesh="leg_middle" density="1000" pos="0.012 0 0.019"/>
          <body pos="0.1015 0 0.002" childclass="knee">
            <joint name="front_right_knee"/>
            <geom type="mesh" mesh="foot_tip_no_foot" density="1000" friction="2.0 0.1 0.1"/>
          </body>
        </body>
      </body>
      

      <!-- Mid Left Leg -->
      <body pos="0 0.1255 0" euler="0 0 90" childclass="yaw" name="mid_left_leg">
        <joint name="mid_left_yaw"/>
        <geom type="mesh" mesh="leg_top" density="1000"/>
        <body pos="0.0527 0 0.005" childclass="pitch">
          <joint name="mid_left_pitch"/>
            <geom type="mesh" mesh="leg_middle" density="1000" pos="0.012 0 0.019"/>
          <body pos="0.1015 0 0.002" childclass="knee">
            <joint name="mid_left_knee"/>
            <geom type="mesh" mesh="foot_tip_no_foot" density="1000" friction="2.0 0.1 0.1"/>
          </body>
        </body>
      </body>

      <!-- Mid Right Leg (scaled) -->
      <body pos="0 -0.1255 0" euler="0 0 -90" childclass="yaw" name="mid_right_leg">
        <joint name="mid_right_yaw"/>
        <geom type="mesh" mesh="leg_top" density="1000"/>
        <body pos="0.0527 0 0.005" childclass="pitch">
          <joint name="mid_right_pitch"/>
            <geom type="mesh" mesh="leg_middle" density="1000" pos="0.012 0 0.019"/>
          <body pos="0.1015 0 0.002" childclass="knee">
            <joint name="mid_right_knee"/>
            <geom type="mesh" mesh="foot_tip_no_foot" density="1000" friction="2.0 0.1 0.1"/>
          </body>
        </body>
      </body>

      <!-- Back Left Leg (scaled) -->
       <body pos="-0.1087 0.06277 0" euler="0 0 150" childclass="yaw" name="back_left_leg">
        <joint name="back_left_yaw"/>
        <geom type="mesh" mesh="leg_top" density="1000"/>
        <body pos="0.0527 0 0.005" childclass="pitch">
          <joint name="back_left_pitch"/>
            <geom type="mesh" mesh="leg_middle" density="1000" pos="0.012 0 0.019"/>
          <body pos="0.1015 0 0.002" childclass="knee">
            <joint name="back_left_knee"/>
            <geom type="mesh" mesh="foot_tip_no_foot" density="1000" friction="2.0 0.1 0.1"/>
          </body>
        </body>
      </body>

      <!-- Back Right Leg (scaled) -->
       <body pos="-0.1087 -0.06277 0" euler="0 0 -150" childclass="yaw" name="back_right_leg">
        <joint name="back_right_yaw"/>
        <geom type="mesh" mesh="leg_top" density="1000"/>
        <body pos="0.0527 0 0.005" childclass="pitch">
          <joint name="back_right_pitch"/>
            <geom type="mesh" mesh="leg_middle" density="1000" pos="0.012 0 0.019"/>
          <body pos="0.1015 0 0.002" childclass="knee">
            <joint name="back_right_knee"/>
            <geom type="mesh" mesh="foot_tip_no_foot" density="1000" friction="2.0 0.1 0.1"/>
          </body>
        </body>
      </body>

    </body>
  </worldbody>

  <actuator>
    <position joint="front_left_yaw" class="yaw" name="front_left_yaw"/>
    <position joint="front_left_pitch" class="pitch" name="front_left_pitch"/>
    <position joint="front_left_knee" class="knee" name="front_left_knee"/>

    <position joint="front_right_yaw" class="yaw" name="front_right_yaw"/>
    <position joint="front_right_pitch" class="pitch" name="front_right_pitch"/>
    <position joint="front_right_knee" class="knee" name="front_right_knee"/>

    <position joint="mid_left_yaw" class="yaw" name="mid_left_yaw"/>
    <position joint="mid_left_pitch" class="pitch" name="mid_left_pitch"/>
    <position joint="mid_left_knee" class="knee" name="mid_left_knee"/>

    <position joint="mid_right_yaw" class="yaw"name="mid_right_yaw"/>
    <position joint="mid_right_pitch" class="pitch" name="mid_right_pitch"/>
    <position joint="mid_right_knee" class="knee" name="mid_right_knee"/>

    <position joint="back_left_yaw" class="yaw" name="back_left_yaw"/>
    <position joint="back_left_pitch" class="pitch" name="back_left_pitch"/>
    <position joint="back_left_knee" class="knee" name="back_left_knee"/>

    <position joint="back_right_yaw" class="yaw" name="back_right_yaw"/>
    <position joint="back_right_pitch" class="pitch"name="back_right_pitch"/>
    <position joint="back_right_knee" class="knee" name="back_right_knee"/>
  </actuator>

  <sensor>
    <framepos name="cam_position" objtype="camera" objname="cam"/>
    <framepos name="body_position" objtype="body" objname="torso"/>
    <framequat name="cam_quaternion" objtype="camera" objname="cam"/>
    <framequat name="body_quaternion" objtype="body" objname="torso"/>
    
    <actuatorfrc actuator="front_left_yaw"/>
    <actuatorfrc actuator="front_left_pitch"/>
    <actuatorfrc actuator="front_left_knee"/>

    <actuatorfrc actuator="front_right_yaw"/>
    <actuatorfrc actuator="front_right_pitch"/>
    <actuatorfrc actuator="front_right_knee"/>

    <actuatorfrc actuator="mid_left_yaw"/>
    <actuatorfrc actuator="mid_left_pitch"/>
    <actuatorfrc actuator="mid_left_knee"/>

    <actuatorfrc actuator="mid_right_yaw"/>
    <actuatorfrc actuator="mid_right_pitch"/>
    <actuatorfrc actuator="mid_right_knee"/>

    <actuatorfrc actuator="back_left_yaw"/>
    <actuatorfrc actuator="back_left_pitch"/>
    <actuatorfrc actuator="back_left_knee"/>

    <actuatorfrc actuator="back_right_yaw"/>
    <actuatorfrc actuator="back_right_pitch"/>
    <actuatorfrc actuator="back_right_knee"/>
  </sensor>
</mujoco>